<?xml version="1.0" encoding="utf-8"?>
<!-- This URDF was automatically created by SolidWorks to URDF Exporter! Originally created by Stephen Brawner (brawner@gmail.com) 
     Commit Version: 1.6.0-4-g7f85cfe  Build Version: 1.6.7995.38578
     For more information, please see http://wiki.ros.org/sw_urdf_exporter -->
<robot
  name="little_robot_2023">
  <link
    name="base_link">
    <inertial>
      <origin
        xyz="2.9701E-11 0.023639 0.012305"
        rpy="0 0 0" />
      <mass
        value="0.07779" />
      <inertia
        ixx="0.00012072"
        ixy="5.3427E-14"
        ixz="3.2492E-15"
        iyy="5.5344E-05"
        iyz="-5.4001E-09"
        izz="0.00017528" />
    </inertial>
    <visual>
      <origin
        xyz="0 0 0"
        rpy="0 0 0" />
      <geometry>
        <mesh
          filename="package://little_robot_2023/meshes/base_link.STL" />
      </geometry>
      <material
        name="">
        <color
          rgba="0.79216 0.81961 0.93333 1" />
      </material>
    </visual>
    <collision>
      <origin
        xyz="0 0 0"
        rpy="0 0 0" />
      <geometry>
        <mesh
          filename="package://little_robot_2023/meshes/base_link.STL" />
      </geometry>
    </collision>
  </link>
  <link
    name="link_1">
    <inertial>
      <origin
        xyz="2.5424E-06 9.684E-17 -0.017788"
        rpy="0 0 0" />
      <mass
        value="0.032972" />
      <inertia
        ixx="2.1467E-05"
        ixy="-3.6793E-22"
        ixz="5.9949E-21"
        iyy="2.097E-05"
        iyz="-5.791E-21"
        izz="2.4394E-05" />
    </inertial>
    <visual>
      <origin
        xyz="0 0 0"
        rpy="0 0 0" />
      <geometry>
        <mesh
          filename="package://little_robot_2023/meshes/link_1.STL" />
      </geometry>
      <material
        name="">
        <color
          rgba="0.79216 0.81961 0.93333 1" />
      </material>
    </visual>
    <collision>
      <origin
        xyz="0 0 0"
        rpy="0 0 0" />
      <geometry>
        <mesh
          filename="package://little_robot_2023/meshes/link_1.STL" />
      </geometry>
    </collision>
  </link>
  <joint
    name="joint_1"
    type="revolute">
    <origin
      xyz="0 0 0.042"
      rpy="3.1416 0 3.1416" />
    <parent
      link="base_link" />
    <child
      link="link_1" />
    <axis
      xyz="0 0 1" />
    <limit
      lower="-1.572"
      upper="1.572"
      effort="0"
      velocity="0" />
  </joint>
  <link
    name="link_2">
    <inertial>
      <origin
        xyz="0.05675 0.0011378 -1.6653E-16"
        rpy="0 0 0" />
      <mass
        value="0.031129" />
      <inertia
        ixx="1.8688E-06"
        ixy="7.1767E-21"
        ixz="1.0685E-13"
        iyy="2.6912E-05"
        iyz="-2.537E-21"
        izz="2.5808E-05" />
    </inertial>
    <visual>
      <origin
        xyz="0 0 0"
        rpy="0 0 0" />
      <geometry>
        <mesh
          filename="package://little_robot_2023/meshes/link_2.STL" />
      </geometry>
      <material
        name="">
        <color
          rgba="0.75294 0.75294 0.75294 1" />
      </material>
    </visual>
    <collision>
      <origin
        xyz="0 0 0"
        rpy="0 0 0" />
      <geometry>
        <mesh
          filename="package://little_robot_2023/meshes/link_2.STL" />
      </geometry>
    </collision>
  </link>
  <joint
    name="joint_2"
    type="revolute">
    <origin
      xyz="0 0 -0.0845"
      rpy="0 0 1.5708" />
    <parent
      link="link_1" />
    <child
      link="link_2" />
    <axis
      xyz="0 -1 0" />
    <limit
      lower="-1.572"
      upper="-1.572"
      effort="0"
      velocity="0" />
  </joint>
  <link
    name="link_3">
    <inertial>
      <origin
        xyz="-0.0012743 -0.04247 -0.00050505"
        rpy="0 0 0" />
      <mass
        value="0.015925" />
      <inertia
        ixx="7.613E-06"
        ixy="-1.8257E-21"
        ixz="4.3843E-08"
        iyy="2.9309E-06"
        iyz="-2.0211E-21"
        izz="5.3893E-06" />
    </inertial>
    <visual>
      <origin
        xyz="0 0 0"
        rpy="0 0 0" />
      <geometry>
        <mesh
          filename="package://little_robot_2023/meshes/link_3.STL" />
      </geometry>
      <material
        name="">
        <color
          rgba="0.79216 0.81961 0.93333 1" />
      </material>
    </visual>
    <collision>
      <origin
        xyz="0 0 0"
        rpy="0 0 0" />
      <geometry>
        <mesh
          filename="package://little_robot_2023/meshes/link_3.STL" />
      </geometry>
    </collision>
  </link>
  <joint
    name="joint_3"
    type="revolute">
    <origin
      xyz="0.1135 0 0"
      rpy="1.5708 -1.5708 0" />
    <parent
      link="link_2" />
    <child
      link="link_3" />
    <axis
      xyz="0 0 1" />
    <limit
      lower="-1.572"
      upper="-1.572"
      effort="0"
      velocity="0" />
  </joint>
</robot>